In Next.js 15, an uncommon bug can occur when using the `async/await` syntax within a `getServerSideProps` function that fetches data from an external API.  If the API request fails or times out, the error isn't properly handled, leading to a blank page or a 500 server error without a clear indication of the problem. This is exacerbated when the error handling is nested within multiple `try...catch` blocks or promises, making debugging difficult.

```javascript
// pages/index.js
export async function getServerSideProps(context) {
  try {
    const res = await fetch('https://api.example.com/data');
    if (!res.ok) {
      // This might not always be caught properly
      throw new Error('Failed to fetch data');
    }
    const data = await res.json();
    return { props: { data } };
  } catch (error) {
    console.error('Error fetching data:', error); 
    // Error handling is not sufficient to produce a meaningful user experience
    return { props: { error: 'Something went wrong' } };
  }
}

function Home({ data, error }) {
  if (error) {
    return <p>Error: {error}</p>;
  }
  return (
    <div>
      {/* ... */}
    </div>
  );
}